<?xml version="1.0"?>
<robot name="limo_xacro" xmlns:xacro="http://ros.org/wiki/xacro">
  <link name="base_footprint"/>

  <joint name="base_joint" type="fixed">
    <parent link="base_footprint"/>
    <child link="base_link"/>
    <origin xyz="0.0 0.0 0.15" rpy="0 0 0"/>
  </joint>
    <!-- Base link -->
    <link name="base_link">
        <visual>
            <origin xyz="0 0 -0.15" rpy="0 0 1.57" />
            <geometry>
                <mesh filename="package://limo_description/meshes/limo_base.dae" scale="1 1 1"/>
            </geometry>
        </visual>
        <collision>
            <!--origin xyz="0 0 -0.15" rpy="0 0 1.57" /-->
            <origin xyz="0 0 0" rpy="0 0 0" />
          <geometry>
              <box size="0.13 0.12 0.1"/>
          </geometry>
        </collision>
    </link>

    <link name="inertial_link">
        <inertial>
            <origin xyz="0.0 0.0 0.0" />
            <mass value="2.1557" />
            <inertia ixx="0.24" ixy="0" ixz="0" 
                     iyy="0.96" iyz="0" 
                     izz="0.96" />
        </inertial>
    </link>

    <joint name="inertial_joint" type="fixed">
        <origin xyz="0 0 0" rpy="0 0 0" />
        <parent link="base_link" />
        <child link="inertial_link" />
    </joint>

        <link name="front_left_wheel_link">
            <inertial>
                <origin xyz="0.0 0.0 0.0" />
                <mass value="0.5" />
                <inertia ixx="0.01055" ixy="0" ixz="0" iyy="0.00075" iyz="0" izz="0.01055" />
            </inertial>
            <visual>
                <origin xyz="0 0 0" rpy="0 0 0" />
                <geometry>
                    <mesh filename="package://limo_description/meshes/limo_wheel.dae" />
                </geometry>
            </visual>
            <collision>
              <origin xyz="0 0.0225 0" rpy="1.57 0 0" />
              <geometry>
                  <cylinder length="0.045" radius="0.045" />
              </geometry>
            </collision>
        </link>

        <joint name="front_left_wheel" type="continuous">
            <parent link="base_link"/>
            <child link="front_left_wheel_link"/>
            <origin
                xyz="0.1 0.065 -0.1"
                rpy="0 0 0" />
            <axis xyz="0 1 0"/>
        </joint>

        <link name="front_right_wheel_link">
            <inertial>
                <origin xyz="0.0 0.0 0.0" />
                <mass value="0.5" />
                <inertia ixx="0.01055" ixy="0" ixz="0" iyy="0.00075" iyz="0" izz="0.01055" />
            </inertial>
            <visual>
                <origin xyz="0 0 0" rpy="0 0 3.14" />
                <geometry>
                    <mesh filename="package://limo_description/meshes/limo_wheel.dae" />
                </geometry>
            </visual>
            <collision>
              <origin xyz="0 -0.0225 0" rpy="1.57 0 0" />
              <geometry>
                  <cylinder length="0.045" radius="0.045" />
              </geometry>
            </collision>
        </link>

        <joint name="front_right_wheel" type="continuous">
            <parent link="base_link"/>
            <child link="front_right_wheel_link"/>
            <origin
                xyz="0.1 -0.065 -0.1"
                rpy="0 0 0" />
            <axis xyz="0 1 0"/>
        </joint>

        <link name="rear_left_wheel_link">
            <inertial>
                <origin xyz="0.0 0.0 0.0 " />
                <mass value="0.5" />
                <inertia ixx="0.01055" ixy="0" ixz="0" iyy="0.00075" iyz="0" izz="0.01055" />
            </inertial>
            <visual>
                <origin xyz="0 0 0" rpy="0 0 0" />
                <geometry>
                    <mesh filename="package://limo_description/meshes/limo_wheel.dae" />
                </geometry>
            </visual>
            <collision>
              <origin xyz="0 0.0225 0" rpy="1.57 0 0" />
              <geometry>
                  <cylinder length="0.045" radius="0.045" />
              </geometry>
            </collision>
        </link>

        <joint name="rear_left_wheel" type="continuous">
            <parent link="base_link"/>
            <child link="rear_left_wheel_link"/>
            <origin
                xyz="-0.1 0.065 -0.1"
                rpy="0 0 0" />
            <axis xyz="0 1 0"/>
        </joint>

        <link name="rear_right_wheel_link">
            <inertial>
                <origin xyz="0.0 0.0 0.0" />
                <mass value="0.5" />
                <inertia ixx="0.01055" ixy="0" ixz="0" iyy="0.00075" iyz="0" izz="0.01055" />
            </inertial>
            <visual>
                <origin xyz="0 0 0" rpy="0 0 3.14" />
                <geometry>
                    <mesh filename="package://limo_description/meshes/limo_wheel.dae" />
                </geometry>
            </visual>
            <collision>
              <origin xyz="0 -0.0225 0" rpy="1.57 0 0" />
              <geometry>
                  <cylinder length="0.045" radius="0.045" />
              </geometry>
            </collision>
        </link>

        <joint name="rear_right_wheel" type="continuous">
            <parent link="base_link"/>
            <child link="rear_right_wheel_link"/>
            <origin
                xyz="-0.1 -0.065 -0.1"
                rpy="0 0 0" />
            <axis xyz="0 1 0"/>
        </joint>


    <joint
      name="limo_mycobot"
      type="fixed">
      <origin
        xyz="-0.01 0.0 0.0"
        rpy="0 0 0" />
      <parent
        link="base_link" />
      <child
        link="joint1" />
    </joint>


  <link name="joint1">
    <visual>
      <geometry>
	     <!--- 0.0 0 -0.04  1.5708 3.14159-->
       <mesh filename="package://mycobot_description/urdf/mycobot/joint1.dae"/>
      </geometry>
      <origin xyz = "0.0 0 0 " rpy = " 0 0 -1.5708"/>
    </visual>
    <collision>
      <geometry>
	     <!--- 0.0 0 -0.04  1.5708 3.14159-->
       <mesh filename="package://mycobot_description/urdf/mycobot/joint1.dae"/>
        </geometry>
        <origin xyz = "0.0 0 0 " rpy = " 0 0 -1.5708"/>
    </collision>
  </link>

  <link name="joint2">
    <visual>
      <geometry>
       <mesh filename="package://mycobot_description/urdf/mycobot/joint2.dae"/>
      </geometry>
      <origin xyz = "0.0 0 -0.06096 " rpy = " 0 0 -1.5708"/>
    </visual>
    <collision>
     <geometry>
       <mesh filename="package://mycobot_description/urdf/mycobot/joint2.dae"/>
      </geometry>
      <origin xyz = "0.0 0 -0.06096 " rpy = " 0 0 -1.5708"/>
    </collision>
  </link>


  <link name="joint3">
    <visual>
      <geometry>
       <mesh filename="package://mycobot_description/urdf/mycobot/joint3.dae"/>
      </geometry>
    <origin xyz = "0.0 0 0.03256 " rpy = " 0 -1.5708 0"/>
    </visual>
    <collision>
      <geometry>
       <mesh filename="package://mycobot_description/urdf/mycobot/joint3.dae"/>
      </geometry>
      <origin xyz = "0.0 0 0.03256 " rpy = " 0 -1.5708 0"/>
    </collision>
  </link>


  <link name="joint4">
    <visual>
      <geometry>
       <!--- 0.0 0 -0.04 -->
       <mesh filename="package://mycobot_description/urdf/mycobot/joint4.dae"/>
      </geometry>
      <origin xyz = "0.0 0 0.03056 " rpy = " 0 -1.5708 0"/>
    </visual>
    <collision>
      <geometry>
       <!--- 0.0 0 -0.04 -->
       <mesh filename="package://mycobot_description/urdf/mycobot/joint4.dae"/>
      </geometry>
      <origin xyz = "0.0 0 0.03056 " rpy = " 0 -1.5708 0"/>
    </collision>
  </link>


  <link name="joint5">
    <visual>
      <geometry>
       <!--- 0.0 0 -0.04 -->
       <mesh filename="package://mycobot_description/urdf/mycobot/joint5.dae"/>
      </geometry>
    <origin xyz = "0.0 0 -0.03356 " rpy = " -1.5708 0 0"/>
    </visual>
    <collision>
       <geometry>
       <!--- 0.0 0 -0.04 -->
       <mesh filename="package://mycobot_description/urdf/mycobot/joint5.dae"/>
      </geometry>
      <origin xyz = "0.0 0 -0.03356 " rpy = " -1.5708 0 0"/>
    </collision>
  </link>


  <link name="joint6">
    <visual>
      <geometry>
       <!--- 0.0 0 -0.04 -->
       <mesh filename="package://mycobot_description/urdf/mycobot/joint6.dae"/>
      </geometry>
    <origin xyz = "0 0.00 -0.038 " rpy = " 0 0 0"/>
    </visual>
    <collision>
      <geometry>
       <!--- 0.0 0 -0.04 -->
       <mesh filename="package://mycobot_description/urdf/mycobot/joint6.dae"/>
      </geometry>
    <origin xyz = "0 0.00 -0.038 " rpy = " 0 0 0"/>
    </collision>
  </link>


  <link name="joint6_flange">
    <visual>
      <geometry>
       <!--- 0.0 0 -0.04 -->
       <mesh filename="package://mycobot_description/urdf/mycobot/joint7.dae"/>
      </geometry>
    <origin xyz = "0.0 0 -0.012 " rpy = " 0 0 0"/>
    </visual>
    <collision>
      <geometry>
       <!--- 0.0 0 -0.04 -->
       <mesh filename="package://mycobot_description/urdf/mycobot/joint7.dae"/>
      </geometry>
    <origin xyz = "0.0 0 -0.012 " rpy = " 0 0 0"/>
    </collision>
  </link>





  <joint name="joint2_to_joint1" type="revolute">
    <axis xyz="0 0 1"/>
    <limit effort = "1000.0" lower = "-3.14" upper = "3.14159" velocity = "0"/>
    <parent link="joint1"/>
    <child link="joint2"/>
    <origin xyz= "0 0 0.13156" rpy = "0 0 0"/>  
  </joint>


  <joint name="joint3_to_joint2" type="revolute">
    <axis xyz="0 0 1"/>
    <limit effort = "1000.0" lower = "-3.14" upper = "3.14159" velocity = "0"/>
    <parent link="joint2"/>
    <child link="joint3"/>
    <origin xyz= "0 0  0" rpy = "0 1.5708 -1.5708"/>  
  </joint>


  <joint name="joint4_to_joint3" type="revolute">
    <axis xyz=" 0 0 1"/>
    <limit effort = "1000.0" lower = "-3.14" upper = "3.14159" velocity = "0"/>
    <parent link="joint3"/>
    <child link="joint4"/>
    <origin xyz= "  -0.1104 0 0   " rpy = "0 0 0"/>  
  </joint>



  <joint name="joint5_to_joint4" type="revolute">
    <axis xyz=" 0 0 1"/>
    <limit effort = "1000.0" lower = "-3.14" upper = "3.14159" velocity = "0"/>
    <parent link="joint4"/>
    <child link="joint5"/>
    <origin xyz= "-0.096 0 0.06462" rpy = "0 0 -1.5708"/>  
  </joint>

  <joint name="joint6_to_joint5" type="revolute">
    <axis xyz="0 0 1"/>
    <limit effort = "1000.0" lower = "-3.14" upper = "3.14159" velocity = "0"/>
    <parent link="joint5"/>
    <child link="joint6"/>
    <origin xyz= "0 -0.07318 0" rpy = "1.5708 -1.5708 0"/>  
  </joint>

  <joint name="joint6output_to_joint6" type="revolute">
    <axis xyz="0 0 1"/>
    <limit effort = "1000.0" lower = "-3.14" upper = "3.14159" velocity = "0"/>
    <parent link="joint6"/>
    <child link="joint6_flange"/>
    <origin xyz= "0 0.0456 0" rpy = "-1.5708 0 0"/>  
  </joint>


    <link name="gripper_finger_link1">
        <visual>
            <origin xyz="0.0 0.0 0"/>
            <geometry>
                <box size="0.04 0.01 0.01" />
            </geometry>
        </visual>
        <collision>
            <geometry>
                <box size="0.04 0.01 0.01" />
            </geometry>
        </collision>
    </link>

    <joint name="finger_joint2" type="fixed">
        <parent link="joint6_flange"/>
        <child link="gripper_finger_link1"/>
        <origin xyz="-0.02 0 0.02" rpy="0.0 1.57 0.0"/>
    </joint>

    <!-- RIGHT GRIPPER AFT LINK -->
    <link name="gripper_finger_link2">
        <visual>
            <origin xyz="0.0 0.0 0"/>
            <geometry>
                <box size="0.04 0.01 0.01" />
            </geometry>
        </visual>
        <collision>
            <geometry>
                <box size="0.04 0.01 0.01" />
            </geometry>
        </collision>
    </link>

    <joint name="grasping_frame_joint" type="fixed">
      <parent link="joint6_flange"/>
      <child link="gripper_finger_link2"/>
      <origin xyz="0.02 0.0 0.02" rpy="0.0 1.57 0.0"/>
    </joint>
</robot>
